Workbook
Name CHActCashBalance: #REF!
Name CHExpenseForcast: #REF!
Name CHFundrasingForcast: #REF!
Name CHManagementForcast: #REF!
Name CHQ4CashAvailableMonth: #REF!
Name CHQ4CashBalance: #REF!
Name CHRevenueForcast: #REF!
Name CHYTDExpense: #REF!
Name CHYTDRevenue: #REF!
Name CHYTDRevenueVariance: #REF!
Name Combined: #REF!
Name CombinedForcastNet: #REF!
Name CombinedYTDExpense: #REF!
Name CombinedYTDExpenseVariance: #REF!
Name CombinedYTDNet: #REF!
Name CombinedYTDNetVariance: #REF!
Name CombinedYTDRevenue: #REF!
Name CombinedYTDVariance: #REF!
Name ConbimedExpenseForcast: #REF!
Name ConbimedProgramExpenseForcast: #REF!
Name NewCountryForcast: #REF!
Name NewCountryForcastVariance: #REF!
Name NewCountryYTD: #REF!
Name NewcountryYTDVariance: #REF!
Name OSCashalance: #REF!
Name OSCashalanceAct: #REF!
Name OSCashEndBalance: #REF!
Name OSExpenseForcast: #REF!
Name OSExpenseForcastRenovation: #REF!
Name OSForcastNet: #REF!
Name OSForcastNetVariance: #REF!
Name OSFundrasingForcast: #REF!
Name OSHKCenterCashBalance: #REF!
Name OSManagementForcast: #REF!
Name OSProgramAnnual: #REF!
Name OSRevenueForcast: #REF!
Name OSRevenueForcastVariance: #REF!
Name OSYTDExpense: #REF!
Name OSYTDExpenseVariance: #REF!
Name OSYTDNet: #REF!
Name OSYTDRevenue: #REF!
Name OSYTDRevenueVariance: #REF!
Name RateOSAnnualVsLast: #REF!
Name RateOSYTDRevenue: #REF!
Name UnresNetAnnual: #REF!
Name UnresNetDiff: #REF!
Name UnresNetYTD: #REF!
Name YTDCashBalance: #REF!
Name YTDMonthOfCash: #REF!

Sheet Notes
A2: 1a. | B2: Source of data: (1a) Transaction list: exported from Quick Book to have information of: payment date, payee, CBL, GL account, bank account, amount.
A3: 1b. | B3: Source of data: (1b) PIT+SI: exported from Quick Book to have information of: salary, Personal Income Tax (PIT), Social Insurance (SI) by every each staff. (in column I memo, I filter key work "PIT", "SI" to copy these transaction to sheet "PIT + SI payment")
A4: 2 | B4: Processing data: salary allocation to have the % allocation of salary, PIT, SI of staff to provinces
A5: 3 | B5: Source of data: VCB bank statement - export from website VCB e-banking, to have the information of order of payment.
A6: 4 | B6: Processing data: Account list to map GL account with PACCOM expense
B7: row highlighted in green - process data mannualy to allocate salay, PIT, SI to provinces by every each staff.
B8: row highlighted in pink - process data mannualy to input the settlement/ advance amount, not cash amount.
B9: row highlighted in blue - process data mannualy to input the C&G from ELC account. Hong prepared a separated C&G for ELC, then Nguyen don’t need to show it here, just input the total amount from ELC C&G.
A12: Source1_GL | B12: Export the source transactions from QBO, remember to filter Account by the following only: 29 Bank VN*; 30 Bank VN*; 31 Bank VN*
B13: Add columns J to Q, with columns J and Q being manual input, the others are formula
B14: filter
A15: Source2_Bank | B15: Export the bank statements for the report period, add column A and assign series numbers to all transactions
A16: Middle File | B16: This tab is created by copy paste the filtered results from tab "Source1_GL", then add columns highlighted in yellow with formula

Sheet Output(link)
C2: OneSky Vietnam
A3: MONTHLY FINANCIAL REPORT | Q3: Input month to print
A4: ="Period: "&TEXT(Q4,"mmm yyyy") -> Period: Jan 1900 | Q4: ='[2](1a)Transactions'!P9 -> 0
D6: 30 Bank VN:Vietnam (VND) | E6: 30 Bank VN:Vietnam (VND) | F6: 30 Bank VN:Vietnam (VND) | G6: 29 Bank VN:Vietnam (USD) | H6: 29 Bank VN:Vietnam (USD) | I6: 29 Bank VN:Vietnam (USD) | J6: 31 Bank VN:Vietnam Sacombank (VND) | K6: 31 Bank VN:Vietnam Sacombank (VND) | L6: 31 Bank VN:Vietnam Sacombank (VND)
C7: DESCRIPTION | D7: Vietcombank - VND | G7: Vietcombank - USD | J7: Sacombank - VND | N7: TOTAL - VND
D8: Current period | E8: C/F from previous months | F8: YTD | G8: Current period | H8: C/F from previous months | I8: YTD | J8: Current period | K8: C/F from previous months | L8: YTD | N8: Current period | O8: C/F from previous months | P8: YTD | S8: QBO
F9: 381123118 | I9: 14720.93 | L9: 0
C10: Beginning Balance | D10: =E13 -> 1032116636 | E10: =F9 -> 381123118 | F10: =F9 -> 381123118 | G10: =H13 -> 2604.43 | H10: =I9 -> 14720.93 | I10: =I9 -> 14720.93 | J10: =K13 -> 36756 | K10: =L9 -> 0 | L10: =L9 -> 0 | P10: =P9 -> 0
C11: Cash in | D11: =D19 -> 0 | E11: =E19 -> 26740970066 | F11: =F19 -> 26740970066 | G11: =G20+G22+G23 -> 0 | H11: =H20+H22+H23 -> 904900 | I11: =I20+I22+I23 -> 904900 | J11: =J19 -> 0 | K11: =K19 -> 36756 | L11: =L19 -> 36756 | N11: =N19 -> 0 | O11: =O19 -> 26518081304 | P11: =P19 -> 26518081304 | R11: Income | S11: 26518306769 | T11: =P11-S11 -> -225465
C12: Cash out | D12: =+D27+D51-D24 -> 0 | E12: =+E27+E51-E24 -> 26089976548 | F12: =+F27+F51-F24 -> 26089976548 | G12: =+G27+G51-G24-G21 -> 0 | H12: =+H27+H51-H24-H21 -> 917016.5 | I12: =+I27+I51-I24-I21 -> 917016.5 | J12: =+J27+J51-J24 -> 0 | K12: =+K27+K51-K24 -> 0 | L12: =+L27+L51-L24 -> 0 | N12: =N27+N51 -> 410584783 | O12: =O27+O51 -> 26245937720 | P12: =P27+P51 -> 26656522503 | R12: Expense (accrual) | S12: 25264622246 | T12: =P27-S12 -> 598238
C13: Ending Balance | D13: =D10+D11-D12 -> 1032116636 | E13: =E10+E11-E12 -> 1032116636 | F13: =F9+F11-F12 -> 1032116636 | G13: =G10+G11-G12 -> 2604.43 | H13: =H10+H11-H12 -> 2604.43 | I13: =I9+I11-I12 -> 2604.43 | J13: =J10+J11-J12 -> 36756 | K13: =K10+K11-K12 -> 36756 | L13: =L9+L11-L12 -> 36756 | T13: -10642772 | U13: 1500 AP movement decrease => expense decrease
T14: 471208089 | U14: Accrual increase => Expense accrual increase
A15: No | C15: DESCRIPTION | D15: Vietcombank - VND | G15: Vietcombank - USD | J15: Sacombank - VND | N15: TOTAL - VND | T15: -494931356 | U15: 1310 FA increase =>asset increase, not expense
D16: Current period | E16: C/F from previous months | F16: YTD | G16: Current period | H16: C/F from previous months | I16: YTD | J16: Current period | K16: C/F from previous months | L16: YTD | N16: Current period | O16: C/F from previous months | P16: YTD
C17: Beginning Balance | D17: =E54 -> 1032116636 | E17: =F9 -> 381123118 | F17: =F9 -> 381123118 | G17: =H54 -> 2604.43 | H17: =I9 -> 14720.93 | I17: =I9 -> 14720.93 | J17: =K54 -> 36756 | K17: =L9 -> 0 | L17: =L9 -> 0 | N17: =O10 -> 0 | O17: =P10 -> 0 | P17: =P10 -> 0
A19: I.A | C19: Income - OS | D19: =SUM(D20:D23) -> 0 | E19: =SUM(E20:E23) -> 26740970066 | F19: =SUM(F20:F23) -> 26740970066 | G19: =SUM(G20:G23) -> 0 | H19: =SUM(H20:H23) -> -9600 | I19: =SUM(I20:I23) -> -9600 | J19: =SUM(J20:J23) -> 0 | K19: =SUM(K20:K23) -> 36756 | L19: =SUM(L20:L23) -> 36756 | N19: =SUM(N20:N23) -> 0 | O19: =SUM(O20:O23) -> 26518081304 | P19: =SUM(P20:P23) -> 26518081304
A20: 1 | B20: Contribution | C20: Contribution | D20: =SUMIFS('[2](1a)Transactions'!$L:$L,'[2](1a)Transactions'!$R:$R,$C20,'[2](1a)Transactions'!$P:$P,$Q$4,'[2](1a)Transactions'!$Q:$Q,"30") -> 0 | E20: ='[1]Output (Oct)'!G21 -> 3100680000 | F20: =SUM(D20:E20) -> 3100680000 | G20: =SUMIFS('[2](1a)Transactions'!$L:$L,'[2](1a)Transactions'!$R:$R,$C20,'[2](1a)Transactions'!$P:$P,$Q$4,'[2](1a)Transactions'!$Q:$Q,"29") -> 0 | H20: ='[1]Output (Oct)'!J21 -> 904900 | I20: =SUM(G20:H20) -> 904900 | J20: =SUMIFS('[2](1a)Transactions'!$L:$L,'[2](1a)Transactions'!$R:$R,$C20,'[2](1a)Transactions'!$P:$P,$Q$4,'[2](1a)Transactions'!$Q:$Q,"31") -> 0 | K20: ='[1]Output (Oct)'!M21 -> 0 | L20: =SUM(J20:K20) -> 0 | N20: =SUMIFS('[2](1a)Transactions'!$I:$I,'[2](1a)Transactions'!$R:$R,$C20,'[2](1a)Transactions'!$P:$P,$Q$4) -> 0 | O20: ='[1]Output (Oct)'!Q21 -> 26516539482 | P20: =SUM(N20:O20) -> 26516539482
A21: 2 | B21: Fund transfer | C21: Fund transfer to USD account | D21: =SUMIFS('[2](1a)Transactions'!$L:$L,'[2](1a)Transactions'!$R:$R,$C21,'[2](1a)Transactions'!$P:$P,$Q$4,'[2](1a)Transactions'!$Q:$Q,"30") -> 0 | E21: ='[1]Output (Oct)'!G22 -> 23638785000 | F21: =SUM(D21:E21) -> 23638785000 | G21: =SUMIFS('[2](1a)Transactions'!$L:$L,'[2](1a)Transactions'!$R:$R,$C21,'[2](1a)Transactions'!$P:$P,$Q$4,'[2](1a)Transactions'!$Q:$Q,"29") -> 0 | H21: ='[1]Output (Oct)'!J22 -> -914500 | I21: =SUM(G21:H21) -> -914500 | J21: =SUMIFS('[2](1a)Transactions'!$L:$L,'[2](1a)Transactions'!$R:$R,$C21,'[2](1a)Transactions'!$P:$P,$Q$4,'[2](1a)Transactions'!$Q:$Q,"31") -> 0 | K21: ='[1]Output (Oct)'!M22 -> 0 | L21: =SUM(J21:K21) -> 0 | N21: =SUMIFS('[2](1a)Transactions'!$I:$I,'[2](1a)Transactions'!$R:$R,$C21,'[2](1a)Transactions'!$P:$P,$Q$4) -> 0 | O21: ='[1]Output (Oct)'!Q22 -> 0 | P21: =SUM(N21:O21) -> 0
A22: 3 | B22: Interest | C22: Interest | D22: =SUMIFS('[2](1a)Transactions'!$L:$L,'[2](1a)Transactions'!$R:$R,$C22,'[2](1a)Transactions'!$P:$P,$Q$4,'[2](1a)Transactions'!$Q:$Q,"30") -> 0 | E22: ='[1]Output (Oct)'!G23 -> 1505066 | F22: =SUM(D22:E22) -> 1505066 | G22: =SUMIFS('[2](1a)Transactions'!$L:$L,'[2](1a)Transactions'!$R:$R,$C22,'[2](1a)Transactions'!$P:$P,$Q$4,'[2](1a)Transactions'!$Q:$Q,"29") -> 0 | H22: ='[1]Output (Oct)'!J23 -> 0 | I22: =SUM(G22:H22) -> 0 | J22: =SUMIFS('[2](1a)Transactions'!$L:$L,'[2](1a)Transactions'!$R:$R,$C22,'[2](1a)Transactions'!$P:$P,$Q$4,'[2](1a)Transactions'!$Q:$Q,"31") -> 0 | K22: ='[1]Output (Oct)'!M23 -> 36756 | L22: =SUM(J22:K22) -> 36756 | N22: =SUMIFS('[2](1a)Transactions'!$I:$I,'[2](1a)Transactions'!$R:$R,$C22,'[2](1a)Transactions'!$P:$P,$Q$4) -> 0 | O22: ='[1]Output (Oct)'!Q23 -> 1541822 | P22: =SUM(N22:O22) -> 1541822
A23: 4 | B23: PED | C23: PED | D23: =SUMIFS('[2](1a)Transactions'!$L:$L,'[2](1a)Transactions'!$R:$R,$C23,'[2](1a)Transactions'!$P:$P,$Q$4,'[2](1a)Transactions'!$Q:$Q,"30") -> 0 | E23: ='[1]Output (Oct)'!G24 -> 0 | F23: =SUM(D23:E23) -> 0 | G23: =SUMIFS('[2](1a)Transactions'!$L:$L,'[2](1a)Transactions'!$R:$R,$C23,'[2](1a)Transactions'!$P:$P,$Q$4,'[2](1a)Transactions'!$Q:$Q,"29") -> 0 | H23: ='[1]Output (Oct)'!J24 -> 0 | I23: =SUM(G23:H23) -> 0 | J23: =SUMIFS('[2](1a)Transactions'!$L:$L,'[2](1a)Transactions'!$R:$R,$C23,'[2](1a)Transactions'!$P:$P,$Q$4,'[2](1a)Transactions'!$Q:$Q,"31") -> 0 | K23: ='[1]Output (Oct)'!M24 -> 0 | L23: =SUM(J23:K23) -> 0 | N23: =SUMIFS('[2](1a)Transactions'!$I:$I,'[2](1a)Transactions'!$R:$R,$C23,'[2](1a)Transactions'!$P:$P,$Q$4) -> 0 | O23: ='[1]Output (Oct)'!Q24 -> 0 | P23: =SUM(N23:O23) -> 0
A24: I.B | C24: Income - ELC | D24: =SUM(D25) -> 0 | E24: =SUM(E25) -> -8592221548 | F24: =SUM(F25) -> -8592221548 | G24: =SUM(G25) -> 0 | H24: =SUM(H25) -> 0 | I24: =SUM(I25) -> 0 | J24: =SUM(J25) -> 0 | K24: =SUM(K25) -> 0 | L24: =SUM(L25) -> 0 | N24: =SUM(N25) -> 0 | O24: =SUM(O25) -> -8592221548 | P24: =SUM(P25) -> -8592221548
A25: 1 | B25: ELC Fund transfer | C25: Fund transfer to ELC | D25: =SUMIFS('[2](1a)Transactions'!$L:$L,'[2](1a)Transactions'!$R:$R,$C25,'[2](1a)Transactions'!$P:$P,$Q$4,'[2](1a)Transactions'!$Q:$Q,"30") -> 0 | E25: ='[1]Output (Oct)'!G26 -> -8592221548 | F25: =SUM(D25:E25) -> -8592221548 | G25: =SUMIFS('[2](1a)Transactions'!$L:$L,'[2](1a)Transactions'!$R:$R,$C25,'[2](1a)Transactions'!$P:$P,$Q$4,'[2](1a)Transactions'!$Q:$Q,"29") -> 0 | H25: ='[1]Output (Oct)'!J26 -> 0 | I25: =SUM(G25:H25) -> 0 | J25: =SUMIFS('[2](1a)Transactions'!$L:$L,'[2](1a)Transactions'!$R:$R,$C25,'[2](1a)Transactions'!$P:$P,$Q$4,'[2](1a)Transactions'!$Q:$Q,"31") -> 0 | K25: ='[1]Output (Oct)'!M26 -> 0 | L25: =SUM(J25:K25) -> 0 | N25: =SUMIFS('[2](1a)Transactions'!$I:$I,'[2](1a)Transactions'!$R:$R,$C25,'[2](1a)Transactions'!$P:$P,$Q$4) -> 0 | O25: ='[1]Output (Oct)'!Q26 -> -8592221548 | P25: =SUM(N25:O25) -> -8592221548
A27: II. A | C27: Expenditure by nature | D27: =SUM(D28:D33) -> 0 | E27: =SUM(E28:E33) -> 16579614564 | F27: =SUM(F28:F33) -> 16579614564 | G27: =SUM(G28:G33) -> 0 | H27: =SUM(H28:H33) -> 16.5 | I27: =SUM(I28:I33) -> 16.5 | J27: =SUM(J28:J33) -> 0 | K27: =SUM(K28:K33) -> 0 | L27: =SUM(L28:L33) -> 0 | N27: =SUM(N28:N33) -> 0 | O27: =SUM(O28:O33) -> 25265220484 | P27: =SUM(P28:P33) -> 25265220484
A28: 1 | B28: Org | C28: Organisational capacity building | D28: =-SUMIFS('[2](1a)Transactions'!$L:$L,'[2](1a)Transactions'!$S:$S,$C28,'[2](1a)Transactions'!$P:$P,$Q$4,'[2](1a)Transactions'!$Q:$Q,"30") -> 0 | E28: ='[1]Output (Oct)'!G29 -> 13363789703 | F28: =SUM(D28:E28) -> 13363789703 | G28: =-SUMIFS('[2](1a)Transactions'!$L:$L,'[2](1a)Transactions'!$S:$S,$C28,'[2](1a)Transactions'!$P:$P,$Q$4,'[2](1a)Transactions'!$Q:$Q,"29") -> 0 | H28: ='[1]Output (Oct)'!J29 -> 0 | I28: =SUM(G28:H28) -> 0 | J28: =-SUMIFS('[2](1a)Transactions'!$L:$L,'[2](1a)Transactions'!$S:$S,$C28,'[2](1a)Transactions'!$P:$P,$Q$4,'[2](1a)Transactions'!$Q:$Q,"31") -> 0 | K28: ='[1]Output (Oct)'!M29 -> 0 | L28: =SUM(J28:K28) -> 0 | N28: =-SUMIFS('[2](1a)Transactions'!$L:$L,'[2](1a)Transactions'!$S:$S,$C28,'[2](1a)Transactions'!$P:$P,$Q$4,'[2](1a)Transactions'!$Q:$Q,"30")-SUMIFS('[2](1a)Transactions'!$L:$L,'[2](1a)Transactions'!$S:$S,$C28,'[2](1a)Transactions'!$P:$P,$Q$4,'[2](1a)Transactions'!$Q:$Q,"29")-SUMIFS('[2](1a)Transactions'!$L:$L,'[2](1a)Transactions'!$S:$S,$C28,'[2](1a)Transactions'!$P:$P,$Q$4,'[2](1a)Transactions'!$Q:$Q,"31") -> 0 | O28: ='[1]Output (Oct)'!Q29 -> 21080045087 | P28: =SUM(N28:O28) -> 21080045087
A29: 2 | B29: Edu | C29: Education quality improvement | D29: =-SUMIFS('[2](1a)Transactions'!$L:$L,'[2](1a)Transactions'!$S:$S,$C29,'[2](1a)Transactions'!$P:$P,$Q$4,'[2](1a)Transactions'!$Q:$Q,"30") -> 0 | E29: ='[1]Output (Oct)'!G30 -> 2476346325 | F29: =SUM(D29:E29) -> 2476346325 | G29: =-SUMIFS('[2](1a)Transactions'!$L:$L,'[2](1a)Transactions'!$S:$S,$C29,'[2](1a)Transactions'!$P:$P,$Q$4,'[2](1a)Transactions'!$Q:$Q,"29") -> 0 | H29: ='[1]Output (Oct)'!J30 -> 0 | I29: =SUM(G29:H29) -> 0 | J29: =-SUMIFS('[2](1a)Transactions'!$L:$L,'[2](1a)Transactions'!$S:$S,$C29,'[2](1a)Transactions'!$P:$P,$Q$4,'[2](1a)Transactions'!$Q:$Q,"31") -> 0 | K29: ='[1]Output (Oct)'!M30 -> 0 | L29: =SUM(J29:K29) -> 0 | N29: =-SUMIFS('[2](1a)Transactions'!$L:$L,'[2](1a)Transactions'!$S:$S,$C29,'[2](1a)Transactions'!$P:$P,$Q$4,'[2](1a)Transactions'!$Q:$Q,"30")-SUMIFS('[2](1a)Transactions'!$L:$L,'[2](1a)Transactions'!$S:$S,$C29,'[2](1a)Transactions'!$P:$P,$Q$4,'[2](1a)Transactions'!$Q:$Q,"29")-SUMIFS('[2](1a)Transactions'!$L:$L,'[2](1a)Transactions'!$S:$S,$C29,'[2](1a)Transactions'!$P:$P,$Q$4,'[2](1a)Transactions'!$Q:$Q,"31") -> 0 | O29: ='[1]Output (Oct)'!Q30 -> 2806818382 | P29: =SUM(N29:O29) -> 2806818382
A30: 3 | B30: Oper | C30: Program Operation | D30: =-SUMIFS('[2](1a)Transactions'!$L:$L,'[2](1a)Transactions'!$S:$S,$C30,'[2](1a)Transactions'!$P:$P,$Q$4,'[2](1a)Transactions'!$Q:$Q,"30") -> 0 | E30: ='[1]Output (Oct)'!G31 -> 739478536 | F30: =SUM(D30:E30) -> 739478536 | G30: =-SUMIFS('[2](1a)Transactions'!$L:$L,'[2](1a)Transactions'!$S:$S,$C30,'[2](1a)Transactions'!$P:$P,$Q$4,'[2](1a)Transactions'!$Q:$Q,"29") -> 0 | H30: ='[1]Output (Oct)'!J31 -> 16.5 | I30: =SUM(G30:H30) -> 16.5 | J30: =-SUMIFS('[2](1a)Transactions'!$L:$L,'[2](1a)Transactions'!$S:$S,$C30,'[2](1a)Transactions'!$P:$P,$Q$4,'[2](1a)Transactions'!$Q:$Q,"31") -> 0 | K30: ='[1]Output (Oct)'!M31 -> 0 | L30: =SUM(J30:K30) -> 0 | N30: =-SUMIFS('[2](1a)Transactions'!$L:$L,'[2](1a)Transactions'!$S:$S,$C30,'[2](1a)Transactions'!$P:$P,$Q$4,'[2](1a)Transactions'!$Q:$Q,"30")-SUMIFS('[2](1a)Transactions'!$L:$L,'[2](1a)Transactions'!$S:$S,$C30,'[2](1a)Transactions'!$P:$P,$Q$4,'[2](1a)Transactions'!$Q:$Q,"29")-SUMIFS('[2](1a)Transactions'!$L:$L,'[2](1a)Transactions'!$S:$S,$C30,'[2](1a)Transactions'!$P:$P,$Q$4,'[2](1a)Transactions'!$Q:$Q,"31") -> 0 | O30: ='[1]Output (Oct)'!Q31 -> 1124628106 | P30: =SUM(N30:O30) -> 1124628106
A31: 4 | B31: Nutrition | C31: Nutrion for the children | D31: =-SUMIFS('[2](1a)Transactions'!$L:$L,'[2](1a)Transactions'!$S:$S,$C31,'[2](1a)Transactions'!$P:$P,$Q$4,'[2](1a)Transactions'!$Q:$Q,"30") -> 0 | E31: ='[1]Output (Oct)'!G32 -> 0 | F31: =SUM(D31:E31) -> 0 | G31: =-SUMIFS('[2](1a)Transactions'!$L:$L,'[2](1a)Transactions'!$S:$S,$C31,'[2](1a)Transactions'!$P:$P,$Q$4,'[2](1a)Transactions'!$Q:$Q,"29") -> 0 | H31: ='[1]Output (Oct)'!J32 -> 0 | I31: =SUM(G31:H31) -> 0 | J31: =-SUMIFS('[2](1a)Transactions'!$L:$L,'[2](1a)Transactions'!$S:$S,$C31,'[2](1a)Transactions'!$P:$P,$Q$4,'[2](1a)Transactions'!$Q:$Q,"31") -> 0 | K31: ='[1]Output (Oct)'!M32 -> 0 | L31: =SUM(J31:K31) -> 0 | N31: =-SUMIFS('[2](1a)Transactions'!$L:$L,'[2](1a)Transactions'!$S:$S,$C31,'[2](1a)Transactions'!$P:$P,$Q$4,'[2](1a)Transactions'!$Q:$Q,"30")-SUMIFS('[2](1a)Transactions'!$L:$L,'[2](1a)Transactions'!$S:$S,$C31,'[2](1a)Transactions'!$P:$P,$Q$4,'[2](1a)Transactions'!$Q:$Q,"29")-SUMIFS('[2](1a)Transactions'!$L:$L,'[2](1a)Transactions'!$S:$S,$C31,'[2](1a)Transactions'!$P:$P,$Q$4,'[2](1a)Transactions'!$Q:$Q,"31") -> 0 | O31: ='[1]Output (Oct)'!Q32 -> 188746159 | P31: =SUM(N31:O31) -> 188746159
A32: 5 | B32: Edu Infra | C32: Education Infrastructure | D32: =-SUMIFS('[2](1a)Transactions'!$L:$L,'[2](1a)Transactions'!$S:$S,$C32,'[2](1a)Transactions'!$P:$P,$Q$4,'[2](1a)Transactions'!$Q:$Q,"30") -> 0 | E32: ='[1]Output (Oct)'!G33 -> 0 | F32: =SUM(D32:E32) -> 0 | G32: =-SUMIFS('[2](1a)Transactions'!$L:$L,'[2](1a)Transactions'!$S:$S,$C32,'[2](1a)Transactions'!$P:$P,$Q$4,'[2](1a)Transactions'!$Q:$Q,"29") -> 0 | H32: ='[1]Output (Oct)'!J33 -> 0 | I32: =SUM(G32:H32) -> 0 | J32: =-SUMIFS('[2](1a)Transactions'!$L:$L,'[2](1a)Transactions'!$S:$S,$C32,'[2](1a)Transactions'!$P:$P,$Q$4,'[2](1a)Transactions'!$Q:$Q,"31") -> 0 | K32: ='[1]Output (Oct)'!M33 -> 0 | L32: =SUM(J32:K32) -> 0 | N32: =-SUMIFS('[2](1a)Transactions'!$L:$L,'[2](1a)Transactions'!$S:$S,$C32,'[2](1a)Transactions'!$P:$P,$Q$4,'[2](1a)Transactions'!$Q:$Q,"30")-SUMIFS('[2](1a)Transactions'!$L:$L,'[2](1a)Transactions'!$S:$S,$C32,'[2](1a)Transactions'!$P:$P,$Q$4,'[2](1a)Transactions'!$Q:$Q,"29")-SUMIFS('[2](1a)Transactions'!$L:$L,'[2](1a)Transactions'!$S:$S,$C32,'[2](1a)Transactions'!$P:$P,$Q$4,'[2](1a)Transactions'!$Q:$Q,"31") -> 0 | O32: ='[1]Output (Oct)'!Q33 -> 64982750 | P32: =SUM(N32:O32) -> 64982750
A34: II. B | C34: Expenditure by Provinces | D34: =SUM(D35:D50) -> 0 | E34: =SUM(E35:E50) -> 16579614564 | F34: =SUM(F35:F50) -> 16579614564 | G34: =SUM(G35:G50) -> 0 | H34: =SUM(H35:H50) -> 2516.5 | I34: =SUM(I35:I50) -> 2516.5 | J34: =SUM(J35:J50) -> 0 | K34: =SUM(K35:K50) -> 0 | L34: =SUM(L35:L50) -> 0 | N34: =SUM(N35:N50) -> -2669241799 | O34: =SUM(O35:O50) -> 2.526522e+10 | P34: =SUM(P35:P50) -> 22595978685
A35: 1 | B35: ELC | C35: ELC Operation | D35: =-SUMIFS('[2](1a)Transactions'!$I:$I,'[2](1a)Transactions'!$P:$P,$Q$4,'[2](1a)Transactions'!$R:$R,VLOOKUP('Output(link)'!$C35,Lookup1_AcctList!$B:$H,7,0),'[2](1a)Transactions'!$Q:$Q,"30") -> 0 | E35: ='[1]Output (Oct)'!G36 -> 194444 | F35: =SUM(D35:E35) -> 194444 | G35: =-SUMIFS('[2](1a)Transactions'!$I:$I,'[2](1a)Transactions'!$P:$P,$Q$4,'[2](1a)Transactions'!$R:$R,VLOOKUP('Output(link)'!$C35,Lookup1_AcctList!$B:$H,7,0),'[2](1a)Transactions'!$Q:$Q,"29") -> 0 | H35: ='[1]Output (Oct)'!J36 -> 0 | I35: =SUM(G35:H35) -> 0 | J35: =-SUMIFS('[2](1a)Transactions'!$I:$I,'[2](1a)Transactions'!$P:$P,$Q$4,'[2](1a)Transactions'!$R:$R,VLOOKUP('Output(link)'!$C35,Lookup1_AcctList!$B:$H,7,0),'[2](1a)Transactions'!$Q:$Q,"31") -> 0 | K35: ='[1]Output (Oct)'!M36 -> 0 | L35: =SUM(J35:K35) -> 0 | N35: =-SUMIFS('[2](1a)Transactions'!$I:$I,'[2](1a)Transactions'!$P:$P,$Q$4,'[2](1a)Transactions'!$R:$R,VLOOKUP('Output(link)'!$C35,Lookup1_AcctList!$B:$H,7,0)) -> 0 | O35: ='[1]Output (Oct)'!Q36 -> 8682821997 | P35: =SUM(N35:O35) -> 8682821997
A36: 2 | B36: VNELC | C36: ELC training | D36: =-SUMIFS('[2](1a)Transactions'!$I:$I,'[2](1a)Transactions'!$P:$P,$Q$4,'[2](1a)Transactions'!$R:$R,VLOOKUP('Output(link)'!$C36,Lookup1_AcctList!$B:$H,7,0),'[2](1a)Transactions'!$Q:$Q,"30") -> 0 | E36: ='[1]Output (Oct)'!G37 -> 1.727597e+09 | F36: =SUM(D36:E36) -> 1.727597e+09 | G36: =-SUMIFS('[2](1a)Transactions'!$I:$I,'[2](1a)Transactions'!$P:$P,$Q$4,'[2](1a)Transactions'!$R:$R,VLOOKUP('Output(link)'!$C36,Lookup1_AcctList!$B:$H,7,0),'[2](1a)Transactions'!$Q:$Q,"29") -> 0 | H36: ='[1]Output (Oct)'!J37 -> 6.6 | I36: =SUM(G36:H36) -> 6.6 | J36: =-SUMIFS('[2](1a)Transactions'!$I:$I,'[2](1a)Transactions'!$P:$P,$Q$4,'[2](1a)Transactions'!$R:$R,VLOOKUP('Output(link)'!$C36,Lookup1_AcctList!$B:$H,7,0),'[2](1a)Transactions'!$Q:$Q,"31") -> 0 | K36: ='[1]Output (Oct)'!M37 -> 0 | L36: =SUM(J36:K36) -> 0 | N36: =-SUMIFS('[2](1a)Transactions'!$I:$I,'[2](1a)Transactions'!$P:$P,$Q$4,'[2](1a)Transactions'!$R:$R,VLOOKUP('Output(link)'!$C36,Lookup1_AcctList!$B:$H,7,0)) -> 0 | O36: ='[1]Output (Oct)'!Q37 -> 1.7277659e+09 | P36: =SUM(N36:O36) -> 1.7277659e+09
A37: 3 | B37: VNHBC | C37: VN General National Training | D37: =-SUMIFS('[2](1a)Transactions'!$I:$I,'[2](1a)Transactions'!$P:$P,$Q$4,'[2](1a)Transactions'!$R:$R,VLOOKUP('Output(link)'!$C37,Lookup1_AcctList!$B:$H,7,0),'[2](1a)Transactions'!$Q:$Q,"30") -> 0 | E37: ='[1]Output (Oct)'!G38 -> 122720188 | F37: =SUM(D37:E37) -> 122720188 | G37: =-SUMIFS('[2](1a)Transactions'!$I:$I,'[2](1a)Transactions'!$P:$P,$Q$4,'[2](1a)Transactions'!$R:$R,VLOOKUP('Output(link)'!$C37,Lookup1_AcctList!$B:$H,7,0),'[2](1a)Transactions'!$Q:$Q,"29") -> 0 | H37: ='[1]Output (Oct)'!J38 -> 0 | I37: =SUM(G37:H37) -> 0 | J37: =-SUMIFS('[2](1a)Transactions'!$I:$I,'[2](1a)Transactions'!$P:$P,$Q$4,'[2](1a)Transactions'!$R:$R,VLOOKUP('Output(link)'!$C37,Lookup1_AcctList!$B:$H,7,0),'[2](1a)Transactions'!$Q:$Q,"31") -> 0 | K37: ='[1]Output (Oct)'!M38 -> 0 | L37: =SUM(J37:K37) -> 0 | N37: =-SUMIFS('[2](1a)Transactions'!$I:$I,'[2](1a)Transactions'!$P:$P,$Q$4,'[2](1a)Transactions'!$R:$R,VLOOKUP('Output(link)'!$C37,Lookup1_AcctList!$B:$H,7,0)) -> -205558779 | O37: ='[1]Output (Oct)'!Q38 -> 122720188 | P37: =SUM(N37:O37) -> -82838591 | Q37: =P37/7 -> -11834084
A38: 4 | B38: VNDN | C38: Da Nang ICC | D38: =-SUMIFS('[2](1a)Transactions'!$I:$I,'[2](1a)Transactions'!$P:$P,$Q$4,'[2](1a)Transactions'!$R:$R,VLOOKUP('Output(link)'!$C38,Lookup1_AcctList!$B:$H,7,0),'[2](1a)Transactions'!$Q:$Q,"30") -> 0 | E38: ='[1]Output (Oct)'!G39 -> 2.7932597e+09 | F38: =SUM(D38:E38) -> 2.7932597e+09 | G38: =-SUMIFS('[2](1a)Transactions'!$I:$I,'[2](1a)Transactions'!$P:$P,$Q$4,'[2](1a)Transactions'!$R:$R,VLOOKUP('Output(link)'!$C38,Lookup1_AcctList!$B:$H,7,0),'[2](1a)Transactions'!$Q:$Q,"29") -> 0 | H38: ='[1]Output (Oct)'!J39 -> 0 | I38: =SUM(G38:H38) -> 0 | J38: =-SUMIFS('[2](1a)Transactions'!$I:$I,'[2](1a)Transactions'!$P:$P,$Q$4,'[2](1a)Transactions'!$R:$R,VLOOKUP('Output(link)'!$C38,Lookup1_AcctList!$B:$H,7,0),'[2](1a)Transactions'!$Q:$Q,"31") -> 0 | K38: ='[1]Output (Oct)'!M39 -> 0 | L38: =SUM(J38:K38) -> 0 | N38: =-SUMIFS('[2](1a)Transactions'!$I:$I,'[2](1a)Transactions'!$P:$P,$Q$4,'[2](1a)Transactions'!$R:$R,VLOOKUP('Output(link)'!$C38,Lookup1_AcctList!$B:$H,7,0)) -> -307016160 | O38: ='[1]Output (Oct)'!Q39 -> 2.7932597e+09 | P38: =SUM(N38:O38) -> 2.4862436e+09
A39: 5 | B39: VNQN | C39: Quang Nam ICC | D39: =-SUMIFS('[2](1a)Transactions'!$I:$I,'[2](1a)Transactions'!$P:$P,$Q$4,'[2](1a)Transactions'!$R:$R,VLOOKUP('Output(link)'!$C39,Lookup1_AcctList!$B:$H,7,0),'[2](1a)Transactions'!$Q:$Q,"30") -> 0 | E39: ='[1]Output (Oct)'!G40 -> 2.4943818e+09 | F39: =SUM(D39:E39) -> 2.4943818e+09 | G39: =-SUMIFS('[2](1a)Transactions'!$I:$I,'[2](1a)Transactions'!$P:$P,$Q$4,'[2](1a)Transactions'!$R:$R,VLOOKUP('Output(link)'!$C39,Lookup1_AcctList!$B:$H,7,0),'[2](1a)Transactions'!$Q:$Q,"29") -> 0 | H39: ='[1]Output (Oct)'!J40 -> 0 | I39: =SUM(G39:H39) -> 0 | J39: =-SUMIFS('[2](1a)Transactions'!$I:$I,'[2](1a)Transactions'!$P:$P,$Q$4,'[2](1a)Transactions'!$R:$R,VLOOKUP('Output(link)'!$C39,Lookup1_AcctList!$B:$H,7,0),'[2](1a)Transactions'!$Q:$Q,"31") -> 0 | K39: ='[1]Output (Oct)'!M40 -> 0 | L39: =SUM(J39:K39) -> 0 | N39: =-SUMIFS('[2](1a)Transactions'!$I:$I,'[2](1a)Transactions'!$P:$P,$Q$4,'[2](1a)Transactions'!$R:$R,VLOOKUP('Output(link)'!$C39,Lookup1_AcctList!$B:$H,7,0)) -> -433448210 | O39: ='[1]Output (Oct)'!Q40 -> 2.4943818e+09 | P39: =SUM(N39:O39) -> 2.0609336e+09
A40: 6 | B40: VNHD | C40: Hai Duong ICC | D40: =-SUMIFS('[2](1a)Transactions'!$I:$I,'[2](1a)Transactions'!$P:$P,$Q$4,'[2](1a)Transactions'!$R:$R,VLOOKUP('Output(link)'!$C40,Lookup1_AcctList!$B:$H,7,0),'[2](1a)Transactions'!$Q:$Q,"30") -> 0 | E40: ='[1]Output (Oct)'!G41 -> 1.7635671e+09 | F40: =SUM(D40:E40) -> 1.7635671e+09 | G40: =-SUMIFS('[2](1a)Transactions'!$I:$I,'[2](1a)Transactions'!$P:$P,$Q$4,'[2](1a)Transactions'!$R:$R,VLOOKUP('Output(link)'!$C40,Lookup1_AcctList!$B:$H,7,0),'[2](1a)Transactions'!$Q:$Q,"29") -> 0 | H40: ='[1]Output (Oct)'!J41 -> 0 | I40: =SUM(G40:H40) -> 0 | J40: =-SUMIFS('[2](1a)Transactions'!$I:$I,'[2](1a)Transactions'!$P:$P,$Q$4,'[2](1a)Transactions'!$R:$R,VLOOKUP('Output(link)'!$C40,Lookup1_AcctList!$B:$H,7,0),'[2](1a)Transactions'!$Q:$Q,"31") -> 0 | K40: ='[1]Output (Oct)'!M41 -> 0 | L40: =SUM(J40:K40) -> 0 | N40: =-SUMIFS('[2](1a)Transactions'!$I:$I,'[2](1a)Transactions'!$P:$P,$Q$4,'[2](1a)Transactions'!$R:$R,VLOOKUP('Output(link)'!$C40,Lookup1_AcctList!$B:$H,7,0)) -> -31761269 | O40: ='[1]Output (Oct)'!Q41 -> 1.7635671e+09 | P40: =SUM(N40:O40) -> 1.7318059e+09
A41: 7 | B41: VNQNg | C41: Quang Ngai ICC | D41: =-SUMIFS('[2](1a)Transactions'!$I:$I,'[2](1a)Transactions'!$P:$P,$Q$4,'[2](1a)Transactions'!$R:$R,VLOOKUP('Output(link)'!$C41,Lookup1_AcctList!$B:$H,7,0),'[2](1a)Transactions'!$Q:$Q,"30") -> 0 | E41: ='[1]Output (Oct)'!G42 -> 683087 | F41: =SUM(D41:E41) -> 683087 | G41: =-SUMIFS('[2](1a)Transactions'!$I:$I,'[2](1a)Transactions'!$P:$P,$Q$4,'[2](1a)Transactions'!$R:$R,VLOOKUP('Output(link)'!$C41,Lookup1_AcctList!$B:$H,7,0),'[2](1a)Transactions'!$Q:$Q,"29") -> 0 | H41: ='[1]Output (Oct)'!J42 -> 0 | I41: =SUM(G41:H41) -> 0 | J41: =-SUMIFS('[2](1a)Transactions'!$I:$I,'[2](1a)Transactions'!$P:$P,$Q$4,'[2](1a)Transactions'!$R:$R,VLOOKUP('Output(link)'!$C41,Lookup1_AcctList!$B:$H,7,0),'[2](1a)Transactions'!$Q:$Q,"31") -> 0 | K41: ='[1]Output (Oct)'!M42 -> 0 | L41: =SUM(J41:K41) -> 0 | N41: =-SUMIFS('[2](1a)Transactions'!$I:$I,'[2](1a)Transactions'!$P:$P,$Q$4,'[2](1a)Transactions'!$R:$R,VLOOKUP('Output(link)'!$C41,Lookup1_AcctList!$B:$H,7,0)) -> 0 | O41: ='[1]Output (Oct)'!Q42 -> 683087 | P41: =SUM(N41:O41) -> 683087
A42: 8 | B42: VNMOET | C42: Preparation and general of MOET | D42: =-SUMIFS('[2](1a)Transactions'!$I:$I,'[2](1a)Transactions'!$P:$P,$Q$4,'[2](1a)Transactions'!$R:$R,VLOOKUP('Output(link)'!$C42,Lookup1_AcctList!$B:$H,7,0),'[2](1a)Transactions'!$Q:$Q,"30") -> 0 | E42: ='[1]Output (Oct)'!G43 -> 5.9219254e+09 | F42: =SUM(D42:E42) -> 5.9219254e+09 | G42: =-SUMIFS('[2](1a)Transactions'!$I:$I,'[2](1a)Transactions'!$P:$P,$Q$4,'[2](1a)Transactions'!$R:$R,VLOOKUP('Output(link)'!$C42,Lookup1_AcctList!$B:$H,7,0),'[2](1a)Transactions'!$Q:$Q,"29") -> 0 | H42: ='[1]Output (Oct)'!J43 -> 0 | I42: =SUM(G42:H42) -> 0 | J42: =-SUMIFS('[2](1a)Transactions'!$I:$I,'[2](1a)Transactions'!$P:$P,$Q$4,'[2](1a)Transactions'!$R:$R,VLOOKUP('Output(link)'!$C42,Lookup1_AcctList!$B:$H,7,0),'[2](1a)Transactions'!$Q:$Q,"31") -> 0 | K42: ='[1]Output (Oct)'!M43 -> 0 | L42: =SUM(J42:K42) -> 0 | N42: =-SUMIFS('[2](1a)Transactions'!$I:$I,'[2](1a)Transactions'!$P:$P,$Q$4,'[2](1a)Transactions'!$R:$R,VLOOKUP('Output(link)'!$C42,Lookup1_AcctList!$B:$H,7,0)) -> -837982606 | O42: ='[1]Output (Oct)'!Q43 -> 5.9219254e+09 | P42: =SUM(N42:O42) -> 5.0839428e+09
B43: VNBD | C43: Binh Duong MOET | D43: =-SUMIFS('[2](1a)Transactions'!$I:$I,'[2](1a)Transactions'!$P:$P,$Q$4,'[2](1a)Transactions'!$R:$R,VLOOKUP('Output(link)'!$C43,Lookup1_AcctList!$B:$H,7,0),'[2](1a)Transactions'!$Q:$Q,"30") -> 0 | E43: ='[1]Output (Oct)'!G44 -> 0 | F43: =SUM(D43:E43) -> 0 | G43: =-SUMIFS('[2](1a)Transactions'!$I:$I,'[2](1a)Transactions'!$P:$P,$Q$4,'[2](1a)Transactions'!$R:$R,VLOOKUP('Output(link)'!$C43,Lookup1_AcctList!$B:$H,7,0),'[2](1a)Transactions'!$Q:$Q,"29") -> 0 | H43: ='[1]Output (Oct)'!J44 -> 0 | I43: =SUM(G43:H43) -> 0 | J43: =-SUMIFS('[2](1a)Transactions'!$I:$I,'[2](1a)Transactions'!$P:$P,$Q$4,'[2](1a)Transactions'!$R:$R,VLOOKUP('Output(link)'!$C43,Lookup1_AcctList!$B:$H,7,0),'[2](1a)Transactions'!$Q:$Q,"31") -> 0 | K43: ='[1]Output (Oct)'!M44 -> 0 | L43: =SUM(J43:K43) -> 0 | N43: =-SUMIFS('[2](1a)Transactions'!$I:$I,'[2](1a)Transactions'!$P:$P,$Q$4,'[2](1a)Transactions'!$R:$R,VLOOKUP('Output(link)'!$C43,Lookup1_AcctList!$B:$H,7,0)) -> 0 | O43: ='[1]Output (Oct)'!Q44 -> 0 | P43: =SUM(N43:O43) -> 0
A44: 9 | B44: VNBG | C44: Bac Giang MOET | D44: =-SUMIFS('[2](1a)Transactions'!$I:$I,'[2](1a)Transactions'!$P:$P,$Q$4,'[2](1a)Transactions'!$R:$R,VLOOKUP('Output(link)'!$C44,Lookup1_AcctList!$B:$H,7,0),'[2](1a)Transactions'!$Q:$Q,"30") -> 0 | E44: ='[1]Output (Oct)'!G45 -> 475745 | F44: =SUM(D44:E44) -> 475745 | G44: =-SUMIFS('[2](1a)Transactions'!$I:$I,'[2](1a)Transactions'!$P:$P,$Q$4,'[2](1a)Transactions'!$R:$R,VLOOKUP('Output(link)'!$C44,Lookup1_AcctList!$B:$H,7,0),'[2](1a)Transactions'!$Q:$Q,"29") -> 0 | H44: ='[1]Output (Oct)'!J45 -> 0 | I44: =SUM(G44:H44) -> 0 | J44: =-SUMIFS('[2](1a)Transactions'!$I:$I,'[2](1a)Transactions'!$P:$P,$Q$4,'[2](1a)Transactions'!$R:$R,VLOOKUP('Output(link)'!$C44,Lookup1_AcctList!$B:$H,7,0),'[2](1a)Transactions'!$Q:$Q,"31") -> 0 | K44: ='[1]Output (Oct)'!M45 -> 0 | L44: =SUM(J44:K44) -> 0 | N44: =-SUMIFS('[2](1a)Transactions'!$I:$I,'[2](1a)Transactions'!$P:$P,$Q$4,'[2](1a)Transactions'!$R:$R,VLOOKUP('Output(link)'!$C44,Lookup1_AcctList!$B:$H,7,0)) -> 0 | O44: ='[1]Output (Oct)'!Q45 -> 475745 | P44: =SUM(N44:O44) -> 475745
A45: 10 | B45: VNLA | C45: Long An MOET | D45: =-SUMIFS('[2](1a)Transactions'!$I:$I,'[2](1a)Transactions'!$P:$P,$Q$4,'[2](1a)Transactions'!$R:$R,VLOOKUP('Output(link)'!$C45,Lookup1_AcctList!$B:$H,7,0),'[2](1a)Transactions'!$Q:$Q,"30") -> 0 | E45: ='[1]Output (Oct)'!G46 -> 231176455 | F45: =SUM(D45:E45) -> 231176455 | G45: =-SUMIFS('[2](1a)Transactions'!$I:$I,'[2](1a)Transactions'!$P:$P,$Q$4,'[2](1a)Transactions'!$R:$R,VLOOKUP('Output(link)'!$C45,Lookup1_AcctList!$B:$H,7,0),'[2](1a)Transactions'!$Q:$Q,"29") -> 0 | H45: ='[1]Output (Oct)'!J46 -> 0 | I45: =SUM(G45:H45) -> 0 | J45: =-SUMIFS('[2](1a)Transactions'!$I:$I,'[2](1a)Transactions'!$P:$P,$Q$4,'[2](1a)Transactions'!$R:$R,VLOOKUP('Output(link)'!$C45,Lookup1_AcctList!$B:$H,7,0),'[2](1a)Transactions'!$Q:$Q,"31") -> 0 | K45: ='[1]Output (Oct)'!M46 -> 0 | L45: =SUM(J45:K45) -> 0 | N45: =-SUMIFS('[2](1a)Transactions'!$I:$I,'[2](1a)Transactions'!$P:$P,$Q$4,'[2](1a)Transactions'!$R:$R,VLOOKUP('Output(link)'!$C45,Lookup1_AcctList!$B:$H,7,0)) -> -38736986 | O45: ='[1]Output (Oct)'!Q46 -> 231176455 | P45: =SUM(N45:O45) -> 192439469
...

Sheet 1230
A1: DR 1230/ CR bank account | G1: Suggest to set rule base on memo description: | H1: Mapping province | I1: Mapping PACCOM
G2: CBL;receivable ABC; vnd xxx | H2: CBL | I2: Advance
G3: CBL;receivable settlement ABC; vnd xxx | H3: CBL | I3: Settlement
A6: RAW DATA FROM QBO | J6: PROCESSING DATA
B7: Date | D7: No. | E7: Posting | F7: Name | G7: Memo/Description | H7: Account | I7: Amount | J7: Exchange Rate | K7: Original currency | L7: Period | M7: Cash Flow by expense | N7: IIB: Expenditure by province | O7: IIA: Expenditure by nature III: Advance, Settlement
B8: 02/17/2025 | F8: Quang Nam DOET | G8: Net off receivable amount VND4937166 | H8: 30 Bank VN:Vietnam (VND) | I8: 4937166 | K8: 4937166 | L8: 22025 | M8: 1230VN Other Receivable VN | N8: VNQN | O8: Settlement
A9: 30 Vietnam (VND) | B9: 04/11/2025 | C9: Cheque Expense | E9: Yes | F9: Thanh Khe DOET | G9: Danang C14_Second advance for session 5-7, management cost - Advance amount; VND31180000, net off: 10365400 | H9: 30 Bank VN:Vietnam (VND) | I9: 10365400 | K9: 10365400 | L9: 42025 | M9: 1230VN Other Receivable VN | N9: VNDN | O9: Settlement
A10: 30 Vietnam (VND) | B10: 05/25/2025 | C10: Deposit | E10: Yes | F10: Hai Chau DOET | G10: Hai Chau DOET settle session 1st-4th - settle:32,905,000, receivable VND3,560,000 | H10: 30 Bank VN:Vietnam (VND) | I10: 3560000 | K10: 3560000 | L10: 52025 | M10: 1230VN Other Receivable VN | N10: VNDN | O10: Settlement
A11: 30 Vietnam (VND) | B11: 06/03/2025 | C11: Cheque Expense | E11: Yes | F11: Cong ty TNHH Grab | G11: VNHBC7200;Deposit for Grab; VND5000000 | H11: 30 Bank VN:Vietnam (VND) | I11: -5000000 | K11: -5000000 | L11: 62025 | M11: 1230VN Other Receivable VN | N11: VNHBC | O11: Advance
A12: 30 Vietnam (VND) | B12: 06/03/2025 | C12: Cheque Expense | E12: Yes | F12: Cong ty Co phan di chuyen Xanh va thong minh GSM | G12: VNHBC7200;Deposit for Xanh SM; VND5000000 | H12: 30 Bank VN:Vietnam (VND) | I12: -5000000 | K12: -5000000 | L12: 62025 | M12: 1230VN Other Receivable VN | N12: VNHBC | O12: Advance
A13: 30 Vietnam (VND) | B13: 06/04/2025 | C13: Deposit | E13: Yes | F13: Thanh Khe DOET | G13: Thanh Khe DoET refund the remaining balance of CH14 | H13: 30 Bank VN:Vietnam (VND) | I13: 3922900 | K13: 3922900 | L13: 62025 | M13: 1230VN Other Receivable VN | N13: VNDN | O13: Settlement
A14: 30 Vietnam (VND) | B14: 06/10/2025 | C14: Deposit | E14: Yes | F14: Ngu Hanh Son DOET | G14: Ngu Hanh Son DOET refund the remaining balance of CH14 | H14: 30 Bank VN:Vietnam (VND) | I14: 3190000 | K14: 3190000 | L14: 62025 | M14: 1230VN Other Receivable VN | N14: VNDN | O14: Settlement
A15: 30 Vietnam (VND) | B15: 06/23/2025 | C15: Deposit | E15: Yes | F15: Quang Nam DOET | G15: Refund the remaining balance amount of Quang Nam ICC - C13+PD3 | H15: 30 Bank VN:Vietnam (VND) | I15: 605848 | K15: 605848 | L15: 62025 | M15: 1230VN Other Receivable VN | N15: VNQN | O15: Settlement
A16: 30 Vietnam (VND) | B16: 07/21/2025 | C16: Cheque Expense | E16: Yes | F16: Le Bich Hong | G16: VNOther7300;Deposit renting new office for 4 years - 32A Phan Dinh Phung ; VND36650000 | H16: 30 Bank VN:Vietnam (VND) | I16: -36650000 | K16: -36650000 | L16: 72025 | M16: 1230VN Other Receivable VN | N16: VNOther | O16: Advance
A17: 30 Vietnam (VND) | B17: 09/18/2025 | C17: Cheque Expense | E17: Yes | F17: Nguyen Hong Kim | G17: VNOther7300;Deposit electronic fee for OSVN office ; VND5200000 | H17: 30 Bank VN:Vietnam (VND) | I17: -5200000 | K17: -5200000 | L17: 92025 | M17: 1230VN Other Receivable VN | N17: VNOther | O17: Advance
A18: 30 Vietnam (VND) | B18: 10/25/2025 | C18: Deposit | E18: Yes | F18: Tuoi Hoa Kindergarten | G18: Tuoi Hoa Kindergarten pay back the remaining amount for the last settlement in 2025 | H18: 30 Bank VN:Vietnam (VND) | I18: 318150 | K18: 318150 | L18: 102025 | M18: 1230VN Other Receivable VN | N18: VNDN | O18: Settlement

Sheet 1500
A1: DR 1500/ CR bank account | G1: Suggest to set rule base on memo description: | H1: Mapping province | I1: Mapping PACCOM
G2: CBL;GL account - ABC; vnd xxx | H2: CBL | I2: GL account
A7: RAW DATA FROM QBO | J7: PROCESSING DATA
B8: Date | D8: No. | E8: Posting | F8: Name | G8: Memo/Description | H8: Account | I8: Amount | J8: Exchange Rate | K8: Original currency | L8: Period | M8: Cash Flow by expense | N8: IIB: Expenditure by province | O8: IIA: Expenditure by nature III: Advance, Settlement
A9: 30 Vietnam (VND) | B9: 09/05/2025 | C9: Cheque Expense | E9: Yes | F9: Công ty TNHH MTV Hop Nhat Thanh | G9: VNELC7200;Airticket DOFA guest (MS Phuong) to Danang for ELC handover ceremony; VND5414000 | H9: 30 Bank VN:Vietnam (VND) | I9: -5414000 | K9: -5414000 | L9: 92025 | M9: 1500VN Accounts Payable - VN | N9: VNELC | O9: Edu
A10: 30 Vietnam (VND) | B10: 09/05/2025 | C10: Cheque Expense | E10: Yes | F10: Cong ty TNHH Thuong Mai va Du lich Noi Bai | G10: VNELC7200;Car rental DOFA guest (MS Phuong) to Danang for ELC handover ceremony; VND756000 | H10: 30 Bank VN:Vietnam (VND) | I10: -756000 | K10: -756000 | L10: 92025 | M10: 1500VN Accounts Payable - VN | N10: VNELC | O10: Edu
A11: 30 Vietnam (VND) | B11: 09/05/2025 | C11: Cheque Expense | E11: Yes | F11: Nguyen Thi Thanh Thanh | G11: VNELC7200;Hotel for Ms. Mai Phuong - MOFA attending ELC handover ; VND1200000 | H11: 30 Bank VN:Vietnam (VND) | I11: -1200000 | K11: -1200000 | L11: 92025 | M11: 1500VN Accounts Payable - VN | N11: VNELC | O11: Edu
A12: 30 Vietnam (VND) | B12: 09/05/2025 | C12: Cheque Expense | E12: Yes | F12: Nguyen Thi Thanh Thanh | G12: VNELC7300;Working lunch with Lien Chieu Ward, DOET, MOFA after ELC handover ceremony; VND9105000 | H12: 30 Bank VN:Vietnam (VND) | I12: -9105000 | K12: -9105000 | L12: 92025 | M12: 1500VN Accounts Payable - VN | N12: VNELC | O12: Edu
A13: 30 Vietnam (VND) | B13: 09/05/2025 | C13: Cheque Expense | E13: Yes | F13: Vo Thi Quynh Thi | G13: VNELC7300;Fruit gift for Mr. Chinh - Chairman of Da Nang for his contribution to ELC (869655 VND) and working dinner with MOFA on 11 Aug 2025 (1252003); VND2121658 | H13: 30 Bank VN:Vietnam (VND) | I13: -2121658 | K13: -2121658 | L13: 92025 | M13: 1500VN Accounts Payable - VN | N13: VNELC | O13: Edu
A14: 30 Vietnam (VND) | B14: 09/08/2025 | C14: Deposit | E14: Yes | F14: Cong ty TNHH My Thuat Hoang Gia Thang | G14: Payback amount - Hoang Gia Thang - due to the wrong account | H14: 30 Bank VN:Vietnam (VND) | I14: 23617800 | K14: 23617800 | L14: 92025 | M14: 1500VN Accounts Payable - VN | N14: VNOther | O14: Oper
A15: 30 Vietnam (VND) | B15: 09/08/2025 | C15: Deposit | E15: Yes | F15: Cong ty TNHH Thuong mai va Dich vu Tong hop Thanh Quang | G15: Payback amount - Thanh Quang company - due to wrong account | H15: 30 Bank VN:Vietnam (VND) | I15: 6600000 | K15: 6600000 | L15: 92025 | M15: 1500VN Accounts Payable - VN | N15: VNOther | O15: Oper
A16: 30 Vietnam (VND) | B16: 09/08/2025 | C16: Deposit | E16: Yes | F16: Cong ty TNHH MTV Han Anh Thinh | G16: Payback amount - Han Anh Thinh due to wrong amount | H16: 30 Bank VN:Vietnam (VND) | I16: 10030000 | K16: 10030000 | L16: 92025 | M16: 1500VN Accounts Payable - VN | N16: VNOther | O16: Oper
A17: 30 Vietnam (VND) | B17: 09/09/2025 | C17: Cheque Expense | E17: Yes | F17: Công ty TNHH Du Lịch và Dịch Vụ SKYLUX | G17: VNELC7200;Car rental to pick up Morgan and guest on the day of ELC hand over ceremony; VND4133600 | H17: 30 Bank VN:Vietnam (VND) | I17: -4133600 | K17: -4133600 | L17: 92025 | M17: 1500VN Accounts Payable - VN | N17: VNELC | O17: Edu
A18: 30 Vietnam (VND) | B18: 09/09/2025 | C18: Deposit | E18: Yes | F18: Truong Mam non Ngoc Lan | G18: Payback amount - Ngoc Lan kindergarten due to wrong account | H18: 30 Bank VN:Vietnam (VND) | I18: 9548800 | K18: 9548800 | L18: 92025 | M18: 1500VN Accounts Payable - VN | N18: VNDN | O18: Edu
A19: 30 Vietnam (VND) | B19: 09/09/2025 | C19: Deposit | E19: Yes | F19: Truong Mam non Sen Hong | G19: Payback amount - Sen Hong kindergarten - due to wrong account | H19: 30 Bank VN:Vietnam (VND) | I19: 2006000 | K19: 2006000 | L19: 92025 | M19: 1500VN Accounts Payable - VN | N19: VNDN | O19: Edu
A20: 30 Vietnam (VND) | B20: 09/09/2025 | C20: Deposit | E20: Yes | F20: Thanh Khe DOET | G20: Payback amount - Hong Dao kindergarten - due to wrong account | H20: 30 Bank VN:Vietnam (VND) | I20: 5676254 | K20: 5676254 | L20: 92025 | M20: 1500VN Accounts Payable - VN | N20: VNDN | O20: Edu
... A43: 30 Vietnam (VND) | B43: 10/31/2025 | C43: Cheque Expense | E43: Yes | F43: Service Center for Foreign Affairs | G43: VNOther7100;OneSky - SI, HI, UI Oct 25; VND229617511 | H43: 30 Bank VN:Vietnam (VND) | I43: -229617511 | K43: -229617511 | L43: 102025 | M43: 1500VN Accounts Payable - VN | N43: VNOther | O43: Org

Sheet 1252
A1: DR 1252/ CR bank account | G1: Suggest to set rule base on memo description: | H1: Mapping province | I1: Mapping PACCOM
G2: CBL;GL account - ABC; vnd xxx | H2: CBL | I2: GL account
A4: RAW DATA FROM QBO | J4: PROCESSING DATA
B5: Date | D5: No. | E5: Posting | F5: Name | G5: Memo/Description | H5: Account | I5: Amount | J5: Exchange Rate | K5: Original currency | L5: Period | M5: Cash Flow by expense | N5: IIB: Expenditure by province | O5: IIA: Expenditure by nature III: Advance, Settlement
A6: 30 Vietnam (VND) | B6: 10/02/2025 | C6: Cheque Expense | E6: Yes | F6: CONG TY CP TU VAN GLOBAL EMBASSY | G6: VNMOET7300211;Payment to Global Embassy for MOET lauching project's event ; VND33993540 | H6: 30 Bank VN:Vietnam (VND) | I6: -33993540 | K6: -33993540 | L6: 102025 | M6: 1252VN Prepaid expenses VN:Prepaid Expenses VN- Estimated settlement | N6: VNMOET | O6: Edu
A7: 30 Vietnam (VND) | B7: 10/02/2025 | C7: Cheque Expense | E7: Yes | F7: Cong ty CP Truyen thong va du lich Dai Viet | G7: VNMOET7300211;Payment for Dai Viet Company for MOET lauching project's event and training course; VND168825600 | H7: 30 Bank VN:Vietnam (VND) | I7: -168825600 | K7: -168825600 | L7: 102025 | M7: 1252VN Prepaid expenses VN:Prepaid Expenses VN- Estimated settlement | N7: VNMOET | O7: Edu
A8: 30 Vietnam (VND) | B8: 10/02/2025 | C8: Cheque Expense | E8: Yes | F8: Cong ty TNHH TM va DL ALOBAY | G8: VNMOET7200211;Payment for airtickets for delegations attending the MOET training and launching project ; VND179000000 | H8: 30 Bank VN:Vietnam (VND) | I8: -179000000 | K8: -179000000 | L8: 102025 | M8: 1252VN Prepaid expenses VN:Prepaid Expenses VN- Estimated settlement | N8: VNMOET | O8: Edu

Sheet Lookup1_AcctList
A1: OneSky Foundation
A2: Account List
B5: Account No. | C5: Account | D5: Type | E5: Detail type | F5: Description | G5: Balance
B6: 71101VN | C6: Com. and ben. for field staff:Compensation for field staff:ECD Training Specialist (TBH) | D6: Expenses | E6: Other Miscellaneous Service Cost | H6: Organisational capacity building
B7: 71102VN | C7: Com. and ben. for field staff:Compensation for field staff:ELC Deputy Director | D7: Expenses | E7: Other Miscellaneous Service Cost | H7: Organisational capacity building
B8: 71103VN | C8: Com. and ben. for field staff:Compensation for field staff:Curriculum Modification (ThucAn | D8: Expenses | E8: Other Miscellaneous Service Cost | H8: Organisational capacity building
B9: 71105VN | C9: Com. and ben. for field staff:Compensation for field staff:HBC Specialist (Chi) | D9: Expenses | E9: Other Miscellaneous Service Cost | H9: Organisational capacity building
B10: 71119VN | C10: Com. and ben. for field staff:Other ben. for field staff:Benefits Prgm Dev VN | D10: Expenses | E10: Other Miscellaneous Service Cost | H10: Organisational capacity building
B11: 71121VN | C11: Com. and ben. for field staff:Compensation for field staff:OneFamily engineering VN (TBH) | D11: Expenses | E11: Other Miscellaneous Service Cost | H11: Organisational capacity building
B12: 71122VN | C12: Com. and ben. for field staff:Compensation for field staff:VN Blended Learning Mgr (Thao) | D12: Expenses | E12: Other Miscellaneous Service Cost | H12: Organisational capacity building
B13: 71131VN | C13: Com. and ben. for field staff:Compensation for field staff:Parenting Mentors VN (Group) | D13: Expenses | E13: Other Miscellaneous Service Cost | H13: Organisational capacity building
B14: 71132VN | C14: Com. and ben. for field staff:Compensation for field staff:Home Daycare Trainers VN (Group | D14: Expenses | E14: Other Miscellaneous Service Cost | H14: Organisational capacity building
B15: 71139VN | C15: Com. and ben. for field staff:Other ben. for field staff:Tax & Benefit Trainer VN | D15: Expenses | E15: Other Miscellaneous Service Cost | H15: Organisational capacity building
B16: 71141VN | C16: Com. and ben. for field staff:Compensation for field staff:MOET staff (Group) | D16: Expenses | E16: Other Miscellaneous Service Cost | H16: Organisational capacity building
B17: 71201VN | C17: Com. and ben. for field staff:Compensation for field staff:Country Director (Sophie) VN | D17: Expenses | E17: Other Miscellaneous Service Cost | H17: Organisational capacity building
... B85: 8300VN | C85: Depreciation and amortization:Depreciation VN | D85: Expenses | E85: Other Miscellaneous Service Cost | H85: Education quality improvement
B86: 1230VN | H86: mannual input
B87: 1250VN | H87: mannual input
B88: 1252VN | H88: mannual input
B89: 1500VN | H89: mannual input
B90: advance | H90: advance by cash
B91: reimbursement | H91: reimbursement
B92: salary | H92: Organisational capacity building
B93: bonus | H93: Organisational capacity building
B94: PIT | H94: Organisational capacity building
B95: SI, | H95: Organisational capacity building
B96: 1 | C96: 2 | D96: 3 | E96: 4 | F96: 5 | G96: 6 | H96: 7 | I96: 8
B97: Provincial Lookup Table
B98: ELC Operation | H98: ELC
B99: ELC training | H99: VNELC | I99: ELC training
B100: In-country program support | H100: VNOther | I100: In support
B101: VN General National Training | H101: VNHBC | I101: General VN
B102: Da Nang ICC | H102: VNDN | I102: DN ICC
B103: Quang Nam ICC | H103: VNQN | I103: QN ICC
B104: Hai Duong ICC | H104: VNHD | I104: HD ICC
B105: Quang Ngai ICC | H105: VNQNg | I105: QNg ICC
B106: Preparation and general of MOET | H106: VNMOET | I106: MOET
B107: Long An MOET | H107: VNLA | I107: MOET LA
B108: HCM MOET | H108: VNHCM | I108: MOET HCM
B109: Binh Duong MOET | H109: VNBD | I109: MOET BD
...

Sheet Lookup2_Allocation
C2: OneSky Vietnam
C3: Salary Allocation Projection - PACCOM report | D3: VNELC | E3: VNDN | F3: VNQN | G3: VNHD | H3: VNQNg | I3: VNMOET | N3: ELC Operation | O3: ELC training | P3: In support | Q3: General VN | R3: DN ICC | S3: QN ICC | T3: HD ICC | U3: QNg ICC | V3: MOET | W3: MOET LA | X3: MOET HCM | Y3: MOET BD | Z3: MOET BN | AA3: MOET BG
D4: 1 | E4: 2 | F4: 3 | G4: 4 | H4: 5 | I4: 6 | J4: 6 Unit | N4: Current booking | AC4: Allocation
B5: Group | C5: Salary Allocation 2024 | D5: ELC | E5: ICC DN | F5: ICC QN | G5: ICC HD | H5: ICC Qng | I5: Dự án tập huấn toàn quốc/ National Training | J5: Total | K5: Note | L5: Portion | M5: Month | N5: ELC Operation | O5: ELC training | P5: In support | Q5: General VN | R5: DN ICC | S5: QN ICC | T5: HD ICC | U5: QNg ICC | V5: MOET | W5: MOET LA | X5: MOET HCM | Y5: MOET BD | Z5: MOET BN | AA5: MOET BG | AB5: Total | AC5: ELC training | AD5: ICC DN | AE5: ICC QN | AF5: ICC HD | AG5: ICC Qng | AH5: Dự án tập huấn toàn quốc/ National Training | AI5: Total
A6: Hien Thi Hien Vo | B6: Support | C6: Hien Thi Hien Vo | D6: 0 | E6: 0.1 | F6: 0.1 | G6: 0.1 | I6: 0.7 | J6: =SUM(D6:I6) -> 1 | L6: 5 | M6: 12024 | N6: 0 | O6: 0 | P6: 0 | Q6: 0 | R6: 0 | S6: 0 | T6: 0 | U6: 0 | V6: 0 | W6: 0 | X6: 0 | Y6: 0 | Z6: 0 | AA6: 0 | AB6: =P6 -> 0 | AC6: =$AB6*D6 -> 0 | AD6: =$AB6*E6 -> 0 | AE6: =$AB6*F6 -> 0 | AF6: =$AB6*G6 -> 0 | AG6: =$AB6*H6 -> 0 | AH6: =$AB6*I6 -> 0 | AI6: =SUM(AC6:AH6) -> 0 | AJ6: =AB6-AI6 -> 0
A7: Thuy Thi Bich Thuy Tran | B7: Support | C7: Sophie Nguyen Thi Bao Nhung | D7: 0 | E7: 0.2 | F7: 0.2 | G7: 0.2 | I7: 0.4 | J7: =SUM(D7:I7) -> 1 | L7: 5 | M7: 12024 | N7: 0 | O7: 0 | P7: 0 | Q7: 0 | R7: 0 | S7: 0 | T7: 0 | U7: 0 | V7: 0 | W7: 0 | X7: 0 | Y7: 0 | Z7: 0 | AA7: 0 | AB7: =P7 -> 0 | AC7: =$AB7*D7 -> 0 | AD7: =$AB7*E7 -> 0 | AE7: =$AB7*F7 -> 0 | AF7: =$AB7*G7 -> 0 | AG7: =$AB7*H7 -> 0 | AH7: =$AB7*I7 -> 0 | AI7: =SUM(AC7:AH7) -> 0 | AJ7: =AB7-AI7 -> 0
A8: Que Chi | B8: MOET | C8: Truong Thi Hai | D8: 0 | E8: 0.2 | F8: 0.2 | G8: 0.2 | I8: 0.4 | J8: =SUM(D8:I8) -> 1 | L8: 5 | M8: 12024 | N8: 0 | O8: 0 | P8: 0 | Q8: 0 | R8: 0 | S8: 0 | T8: 0 | U8: 0 | V8: 0 | W8: 0 | X8: 0 | Y8: 0 | Z8: 0 | AA8: 0 | AB8: =V8 -> 0 | AC8: =$AB8*D8 -> 0 | AD8: =$AB8*E8 -> 0 | AE8: =$AB8*F8 -> 0 | AF8: =$AB8*G8 -> 0 | AG8: =$AB8*H8 -> 0 | AH8: =$AB8*I8 -> 0 | AI8: =SUM(AC8:AH8) -> 0 | AJ8: =AB8-AI8 -> 0
A9: Maggie Huyen Nguyen | B9: MOET | C9: Huynh My Ngoc | D9: 0 | E9: 0 | F9: 0 | G9: 0 | I9: 1 | J9: =SUM(D9:I9) -> 1 | L9: 100% MOET | M9: 12024 | N9: 0 | O9: 0 | P9: 0 | Q9: 0 | R9: 0 | S9: 0 | T9: 0 | U9: 0 | V9: 0 | W9: 0 | X9: 0 | Y9: 0 | Z9: 0 | AA9: 0 | AB9: =V9 -> 0 | AC9: =$AB9*D9 -> 0 | AD9: =$AB9*E9 -> 0 | AE9: =$AB9*F9 -> 0 | AF9: =$AB9*G9 -> 0 | AG9: =$AB9*H9 -> 0 | AH9: =$AB9*I9 -> 0 | AI9: =SUM(AC9:AH9) -> 0 | AJ9: =AB9-AI9 -> 0
A10: Sophie Nguyen Thi Bao Nhung | B10: MOET | C10: Bui Thi Huong | D10: 0 | E10: 0 | F10: 0 | G10: 0 | I10: 1 | J10: =SUM(D10:I10) -> 1 | L10: 100% MOET | M10: 12024 | N10: 0 | O10: 0 | P10: 0 | Q10: 0 | R10: 0 | S10: 0 | T10: 0 | U10: 0 | V10: 0 | W10: 0 | X10: 0 | Y10: 0 | Z10: 0 | AA10: 0 | AB10: =V10 -> 0 | AC10: =$AB10*D10 -> 0 | AD10: =$AB10*E10 -> 0 | AE10: =$AB10*F10 -> 0 | AF10: =$AB10*G10 -> 0 | AG10: =$AB10*H10 -> 0 | AH10: =$AB10*I10 -> 0 | AI10: =SUM(AC10:AH10) -> 0 | AJ10: =AB10-AI10 -> 0
A11: Nguyen Hong Kim | B11: HBC | C11: Hoang Thi Kieu Oanh | D11: 0 | E11: 0.2 | F11: 0.2 | G11: 0.2 | I11: 0.4 | J11: =SUM(D11:I11) -> 1 | K11: done | L11: 5 | M11: 12024 | N11: 0 | O11: 0 | P11: 0 | Q11: 0 | R11: 0 | S11: 0 | T11: 0 | U11: 0 | V11: 0 | W11: 0 | X11: 0 | Y11: 0 | Z11: 0 | AA11: 0 | AB11: =Q11 -> 0 | AC11: =$AB11*D11 -> 0 | AD11: =$AB11*E11 -> 0 | AE11: =$AB11*F11 -> 0 | AF11: =$AB11*G11 -> 0 | AG11: =$AB11*H11 -> 0 | AH11: =$AB11*I11 -> 0 | AI11: =SUM(AC11:AH11) -> 0 | AJ11: =AB11-AI11 -> 0
A12: Hoang Thi Kieu Oanh | B12: HBC | C12: Phan Doan Kim Nhung | D12: 0 | E12: 0.2 | F12: 0.2 | G12: 0.2 | I12: 0.4 | J12: =SUM(D12:I12) -> 1 | K12: done | L12: 5 | M12: 12024 | N12: 0 | O12: 0 | P12: 0 | Q12: 0 | R12: 0 | S12: 0 | T12: 0 | U12: 0 | V12: 0 | W12: 0 | X12: 0 | Y12: 0 | Z12: 0 | AA12: 0 | AB12: =Q12 -> 0 | AC12: =$AB12*D12 -> 0 | AD12: =$AB12*E12 -> 0 | AE12: =$AB12*F12 -> 0 | AF12: =$AB12*G12 -> 0 | AG12: =$AB12*H12 -> 0 | AH12: =$AB12*I12 -> 0 | AI12: =SUM(AC12:AH12) -> 0 | AJ12: =AB12-AI12 -> 0
A13: Phan Doan Kim Nhung | B13: MOET | C13: Le Thi Thu Huyen | D13: 0 | E13: 0.2 | F13: 0.2 | G13: 0.2 | I13: 0.4 | J13: =SUM(D13:I13) -> 1 | L13: 5 | M13: 12024 | N13: 0 | O13: 0 | P13: 0 | Q13: 0 | R13: 0 | S13: 0 | T13: 0 | U13: 0 | V13: 0 | W13: 0 | X13: 0 | Y13: 0 | Z13: 0 | AA13: 0 | AB13: =V13 -> 0 | AC13: =$AB13*D13 -> 0 | AD13: =$AB13*E13 -> 0 | AE13: =$AB13*F13 -> 0 | AF13: =$AB13*G13 -> 0 | AG13: =$AB13*H13 -> 0 | AH13: =$AB13*I13 -> 0 | AI13: =SUM(AC13:AH13) -> 0 | AJ13: =AB13-AI13 -> 0
A14: Pham Thi Dieu Loan | B14: Support | C14: Thuy Thi Bich Thuy Tran | D14: 0.5 | E14: 0.1 | F14: 0.1 | G14: 0.1 | I14: 0.2 | J14: =SUM(D14:I14) -> 1 | L14: 5 | M14: 12024 | N14: 0 | O14: 0 | P14: 0 | Q14: 0 | R14: 0 | S14: 0 | T14: 0 | U14: 0 | V14: 0 | W14: 0 | X14: 0 | Y14: 0 | Z14: 0 | AA14: 0 | AB14: =P14 -> 0 | AC14: =$AB14*D14 -> 0 | AD14: =$AB14*E14 -> 0 | AE14: =$AB14*F14 -> 0 | AF14: =$AB14*G14 -> 0 | AG14: =$AB14*H14 -> 0 | AH14: =$AB14*I14 -> 0 | AI14: =SUM(AC14:AH14) -> 0 | AJ14: =AB14-AI14 -> 0
A15: Dang Thanh Canh | B15: Support | C15: Maggie Huyen Nguyen | D15: 0 | E15: 0.17 | F15: 0.17 | G15: 0.17 | I15: 0.49 | J15: =SUM(D15:I15) -> 1 | L15: 6 | M15: 12024 | N15: 0 | O15: 0 | P15: 0 | Q15: 0 | R15: 0 | S15: 0 | T15: 0 | U15: 0 | V15: 0 | W15: 0 | X15: 0 | Y15: 0 | Z15: 0 | AA15: 0 | AB15: =P15 -> 0 | AC15: =$AB15*D15 -> 0 | AD15: =$AB15*E15 -> 0 | AE15: =$AB15*F15 -> 0 | AF15: =$AB15*G15 -> 0 | AG15: =$AB15*H15 -> 0 | AH15: =$AB15*I15 -> 0 | AI15: =SUM(AC15:AH15) -> 0 | AJ15: =AB15-AI15 -> 0
A16: Alice Do Kim Dung | B16: Support | C16: Nguyen Hong Kim | D16: 0 | E16: 0.1 | F16: 0.1 | G16: 0.1 | I16: 0.7 | J16: =SUM(D16:I16) -> 1 | L16: 5 | M16: 12024 | N16: 0 | O16: 0 | P16: 0 | Q16: 0 | R16: 0 | S16: 0 | T16: 0 | U16: 0 | V16: 0 | W16: 0 | X16: 0 | Y16: 0 | Z16: 0 | AA16: 0 | AB16: =P16 -> 0 | AC16: =$AB16*D16 -> 0 | AD16: =$AB16*E16 -> 0 | AE16: =$AB16*F16 -> 0 | AF16: =$AB16*G16 -> 0 | AG16: =$AB16*H16 -> 0 | AH16: =$AB16*I16 -> 0 | AI16: =SUM(AC16:AH16) -> 0 | AJ16: =AB16-AI16 -> 0
A17: Truong Thi Hai | B17: Support | C17: Dang Thanh Canh | D17: 0 | E17: 0.17 | F17: 0.17 | G17: 0.17 | I17: 0.49 | J17: =SUM(D17:I17) -> 1 | L17: 6 | M17: 12024 | N17: 0 | O17: 0 | P17: 0 | Q17: 0 | R17: 0 | S17: 0 | T17: 0 | U17: 0 | V17: 0 | W17: 0 | X17: 0 | Y17: 0 | Z17: 0 | AA17: 0 | AB17: =P17 -> 0 | AC17: =$AB17*D17 -> 0 | AD17: =$AB17*E17 -> 0 | AE17: =$AB17*F17 -> 0 | AF17: =$AB17*G17 -> 0 | AG17: =$AB17*H17 -> 0 | AH17: =$AB17*I17 -> 0 | AI17: =SUM(AC17:AH17) -> 0 | AJ17: =AB17-AI17 -> 0
A18: Le Thi Thu Huyen | B18: Support | C18: Nguyen Thi Thanh Thanh | D18: 0 | E18: 0.17 | F18: 0.17 | G18: 0.17 | I18: 0.49 | J18: =SUM(D18:I18) -> 1 | L18: 6 | M18: 12024 | N18: 0 | O18: 0 | P18: 0 | Q18: 0 | R18: 0 | S18: 0 | T18: 0 | U18: 0 | V18: 0 | W18: 0 | X18: 0 | Y18: 0 | Z18: 0 | AA18: 0 | AB18: =P18 -> 0 | AC18: =$AB18*D18 -> 0 | AD18: =$AB18*E18 -> 0 | AE18: =$AB18*F18 -> 0 | AF18: =$AB18*G18 -> 0 | AG18: =$AB18*H18 -> 0 | AH18: =$AB18*I18 -> 0 | AI18: =SUM(AC18:AH18) -> 0 | AJ18: =AB18-AI18 -> 0
A19: Huynh My Ngoc | B19: Support | C19: Phan Thi Thao Nguyen | D19: 0 | E19: 0.17 | F19: 0.17 | G19: 0.17 | I19: 0.49 | J19: =SUM(D19:I19) -> 1 | L19: 6 | M19: 12024 | N19: 0 | O19: 0 | P19: 0 | Q19: 0 | R19: 0 | S19: 0 | T19: 0 | U19: 0 | V19: 0 | W19: 0 | X19: 0 | Y19: 0 | Z19: 0 | AA19: 0 | AB19: =P19 -> 0 | AC19: =$AB19*D19 -> 0 | AD19: =$AB19*E19 -> 0 | AE19: =$AB19*F19 -> 0 | AF19: =$AB19*G19 -> 0 | AG19: =$AB19*H19 -> 0 | AH19: =$AB19*I19 -> 0 | AI19: =SUM(AC19:AH19) -> 0 | AJ19: =AB19-AI19 -> 0
A20: Bui Thi Huong | B20: HBC | C20: Tran Thi Que Chi | D20: 0 | E20: 0.2 | F20: 0.2 | G20: 0.2 | I20: 0.4 | J20: =SUM(D20:I20) -> 1 | L20: 5 | M20: 12024 | N20: 0 | O20: 0 | P20: 0 | Q20: 0 | R20: 0 | S20: 0 | T20: 0 | U20: 0 | V20: 0 | W20: 0 | X20: 0 | Y20: 0 | Z20: 0 | AA20: 0 | AB20: =Q20 -> 0 | AC20: =$AB20*D20 -> 0 | AD20: =$AB20*E20 -> 0 | AE20: =$AB20*F20 -> 0 | AF20: =$AB20*G20 -> 0 | AG20: =$AB20*H20 -> 0 | AH20: =$AB20*I20 -> 0 | AI20: =SUM(AC20:AH20) -> 0 | AJ20: =AB20-AI20 -> 0
A21: Tran Thi Que Chi | B21: HBC | C21: Pham Thi Dieu Loan | D21: 0 | E21: 0.2 | F21: 0.2 | G21: 0.2 | I21: 0.4 | J21: =SUM(D21:I21) -> 1 | L21: 5 | M21: 12024 | N21: 0 | O21: 0 | P21: 0 | Q21: 0 | R21: 0 | S21: 0 | T21: 0 | U21: 0 | V21: 0 | W21: 0 | X21: 0 | Y21: 0 | Z21: 0 | AA21: 0 | AB21: =Q21 -> 0 | AC21: =$AB21*D21 -> 0 | AD21: =$AB21*E21 -> 0 | AE21: =$AB21*F21 -> 0 | AF21: =$AB21*G21 -> 0 | AG21: =$AB21*H21 -> 0 | AH21: =$AB21*I21 -> 0 | AI21: =SUM(AC21:AH21) -> 0 | AJ21: =AB21-AI21 -> 0
A22: Phan Thi Thảo Nguyên | B22: ELC | C22: Alice Do Kim Dung | D22: 0 | E22: 0 | F22: 0 | G22: 0 | I22: 1 | J22: =SUM(D22:I22) -> 1 | L22: 100% ELC | M22: 12024 | N22: 0 | O22: 0 | P22: 0 | Q22: 0 | R22: 0 | S22: 0 | T22: 0 | U22: 0 | V22: 0 | W22: 0 | X22: 0 | Y22: 0 | Z22: 0 | AA22: 0 | AB22: =O22 -> 0 | AC22: =$AB22*D22 -> 0 | AD22: =$AB22*E22 -> 0 | AE22: =$AB22*F22 -> 0 | AF22: =$AB22*G22 -> 0 | AG22: =$AB22*H22 -> 0 | AH22: =$AB22*I22 -> 0 | AI22: =SUM(AC22:AH22) -> 0 | AJ22: =AB22-AI22 -> 0
A24: Vietnam Tax Company | O24: =SUM(O22) -> 0 | P24: =SUM(P6:P7,P14:P19) -> 0 | Q24: =SUM(Q11,Q12,Q20,Q21) -> 0 | V24: =SUM(V8,V9,V10,V11,V13) -> 0 | AB24: =SUM(N24:AA24) -> 0 | AC24: =SUM(AC6:AC23) -> 0 | AD24: =SUM(AD6:AD23) -> 0 | AE24: =SUM(AE6:AE23) -> 0 | AF24: =SUM(AF6:AF23) -> 0 | AG24: =SUM(AG6:AG23) -> 0 | AH24: =SUM(AH6:AH23) -> 0 | AI24: =SUM(AI6:AI23) -> 0
